<?xml version="1.0" encoding="UTF-8"?>
<!-- Generated by org.testng.reporters.JUnitReportReporter -->
<testsuite hostname="LETHI-JUL21-CI" failures="1" tests="4" name="FirstAutomation.Tests.ErrorValidationTest" time="34.112" errors="0" timestamp="2022-10-23T11:15:48 BST" skipped="2">
  <testcase classname="FirstAutomation.Tests.ErrorValidationTest" name="LoginErrorValidation" time="6.458">
    <failure message="expected [Incorrect email or password.] but found [Incorrect email@ or password.]" type="java.lang.AssertionError">
      <![CDATA[java.lang.AssertionError: expected [Incorrect email or password.] but found [Incorrect email@ or password.]
at org.testng.Assert.fail(Assert.java:110)
at org.testng.Assert.failNotEquals(Assert.java:1413)
at org.testng.Assert.assertEqualsImpl(Assert.java:149)
at org.testng.Assert.assertEquals(Assert.java:131)
at org.testng.Assert.assertEquals(Assert.java:655)
at org.testng.Assert.assertEquals(Assert.java:665)
at FirstAutomation.Tests.ErrorValidationTest.LoginErrorValidation(ErrorValidationTest.java:25)
at java.base/jdk.internal.reflect.DirectMethodHandleAccessor.invoke(DirectMethodHandleAccessor.java:104)
at java.base/java.lang.reflect.Method.invoke(Method.java:577)
at org.testng.internal.invokers.MethodInvocationHelper.invokeMethod(MethodInvocationHelper.java:139)
at org.testng.internal.invokers.TestInvoker.invokeMethod(TestInvoker.java:677)
at org.testng.internal.invokers.TestInvoker.retryFailed(TestInvoker.java:263)
at org.testng.internal.invokers.MethodRunner.runInSequence(MethodRunner.java:62)
at org.testng.internal.invokers.TestInvoker$MethodInvocationAgent.invoke(TestInvoker.java:962)
at org.testng.internal.invokers.TestInvoker.invokeTestMethods(TestInvoker.java:194)
at org.testng.internal.invokers.TestMethodWorker.invokeTestMethods(TestMethodWorker.java:148)
at org.testng.internal.invokers.TestMethodWorker.run(TestMethodWorker.java:128)
at java.base/java.util.ArrayList.forEach(ArrayList.java:1511)
at org.testng.TestRunner.privateRun(TestRunner.java:806)
at org.testng.TestRunner.run(TestRunner.java:601)
at org.testng.SuiteRunner.runTest(SuiteRunner.java:433)
at org.testng.SuiteRunner$SuiteWorker.run(SuiteRunner.java:471)
at org.testng.internal.thread.ThreadUtil.lambda$execute$0(ThreadUtil.java:58)
at java.base/java.util.concurrent.FutureTask.run(FutureTask.java:264)
at java.base/java.util.concurrent.ThreadPoolExecutor.runWorker(ThreadPoolExecutor.java:1136)
at java.base/java.util.concurrent.ThreadPoolExecutor$Worker.run(ThreadPoolExecutor.java:635)
at java.base/java.lang.Thread.run(Thread.java:833)
]]>
    </failure>
  </testcase> <!-- LoginErrorValidation -->
  <system-out/>
  <testcase classname="FirstAutomation.Tests.ErrorValidationTest" name="ProductErrorValidation" time="13.848"/>
  <system-out/>
  <testcase classname="FirstAutomation.Tests.ErrorValidationTest" name="LoginErrorValidation" time="6.787">
    <skipped/>
  </testcase> <!-- LoginErrorValidation -->
  <system-out/>
  <testcase classname="FirstAutomation.Tests.ErrorValidationTest" name="LoginErrorValidation" time="7.019">
    <skipped/>
  </testcase> <!-- LoginErrorValidation -->
  <system-out/>
</testsuite> <!-- FirstAutomation.Tests.ErrorValidationTest -->
